Workbook

Sheet Variable_List
B2: Variable | C2: Description | D2: Unit | E2: Comment
B3: Primary Production | C3: Domestic primary production of resources | D3: PJ/yr.
B4: Imports | C4: Imports of energy carriers | D4: PJ/yr.
B5: Exports | C5: Exports of energy carriers | D5: PJ/yr.
B6: Electricity generation | C6: Domestic electricity generation | D6: PJ/yr.
B7: Heat generation from CHPs and heat plants | C7: Domestic heat production from CHPs (District heating CHPs or onsite CHPs) and heat plants | D7: PJ/yr.
B8: Fuel input for electricity generation | C8: Fuel input allocated to domestic electricity generation only | D8: PJ/yr.
B9: Fuel input for heat generation from CHPs and heat plants | C9: Fuel input allocated to domestic heat production from CHPs and heat plants only | D9: PJ/yr.
B10: Efficiency of power plants (electric) | C10: Average annual efficiency of power plants and CHPs for electricity production only | D10: % | E10: The thermal efficiency of CHPs can be inferred from the Heat to Electricity production ratio, but it can also be provided; the average efficiency differs from the technical efficiency as it includes efficiency losses due to part load operation
B11: Efficiency of heat plants (thermal) | C11: Average annual efficiency of heat plants | D11: % | E11: It is the annual marketed efficiency including part load efficiency losses and differs from the full load nominal technical efficiency; for heat pumps refers to COP
B12: Domestic biodiesel production | C12: Domestic production of biodiesel | D12: PJ/yr.
B13: Heat from domestic biodiesel production | C13: Heat produced as byproduct from biodiesel production and fed into the district heating network | D13: PJ/yr.
B14: Fuel input for domestic biodiesel production | C14: Fuel input for the domestic production of biodiesel | D14: PJ/yr.
B15: Efficiency for domestic biodiesel production | C15: Average annual efficiency for biodiesel and heat production | D15: %
B16: Domestic ethanol production | C16: Domestic production of ethanol | D16: PJ/yr.
B17: Fuel input for domestic ethanol production | C17: Fuel input for the domestic production of ethanol | D17: PJ/yr.
B18: Efficiency for domestic ethanol production | C18: Average annual efficiency for domestic production of ethanol | D18: %
B19: Domestic biogas production | C19: Domestic production of biogas and biogenic syngas | D19: PJ/yr.
B20: Electricity from domestic biogas production | C20: Electriicty produced as byproduct from biogas production and fed into the grid | D20: PJ/yr.
B21: Heat from domestic biogas production | C21: Heat produced as byproduct from biogas production and fed into the district heating network | D21: PJ/yr.
B22: Fuel input for domestic biogas production | C22: Fuel input for domestic biogas production | D22: PJ/yr.
B23: Efficiency for domestic biogas production | C23: Average annual efficiency for biogas production (accounting for byproduct production) | D23: %
... B25: Fuel input for hydrogen production | C25: Fuel input for deomstic hydrogen production | D25: PJ/yr.
B26: Efficiency for hydrogen production | C26: Average annual efficiency for hydrogen production | D26: % | E26: Including losses due to part load operation
B27: Biomethane production from biogas upgrade | C27: Production of domestic biomethane from biogas | D27: PJ/yr. | E27: One technology only fuel output is biomethane
B28: Fuel input for biogas upgrade to biomethane | C28: Use of biogas for upgrade to biomethane | D28: PJ/yr. | E28: One technology only fuel input is biogas
B29: Efficiency for biomethane production from biogas upgrade | C29: Average annual efficiency of biogas to biomethane upgrade | D29: PJ/yr. | E29: One technology only fuel input is biogas, fuel output is biomethane
B30: Domestic PtG and PtL production | C30: Domestic production of power-to-gas and power-to-liquids | D30: PJ/yr.
B31: Fuel input for domestic PtG and PtL production | C31: Fuel used for domestic PtG and PtL production (excl. CO2) | D31: PJ/yr.
B32: Efficiency for domestic PtG and PtL production | C32: Average annual efficiency for PtG and PtL processes (excl. CO2 consumption) | D32: %
B33: CO2 input for domestic PtG and PtL production | C33: CO2 input for domestic PtG and PtL production | D33: Mt/yr. | E33: The distinction of the source of CO2 (biogenic or fossil) is also provided and can be proportionally allocated to the technologies for PtG and PtL
B34: Domestic wood to pellet production | C34: Wood conversion to pellet domestic production output | D34: PJ/yr. | E34: One technology only , input is wood output is pellet
B35: Fuel input for wood to pellet production | C35: Wood conversion to pellet domestic production - input wood required | D35: PJ/yr. | E35: One technology only , input is wood output is pellet
B36: Efficiency for wood to pellet production | C36: Average annual efficiency of wood to pellet conversion | D36: %
B37: Fuel consumption in industry sectors | C37: Fuel consumption in industry by fuel and technology | D37: PJ/yr. | E37: This unfortunately it will change when the new industrial sectors will be integrated into STEM
B38: Process and space heating production in industry sectors | C38: Energy service demand provided in the form of process and space heating in industry | D38: PJ/yr. | E38: This unfortunately it will change when the new industrial sectors will be integrated into STEM
B39: Efficiency in industry sectors | C39: Boilers efficiency and COP of heat pumps in the industrial sectors | D39: % | E39: This unfortunately it will change when the new industrial sectors will be integrated into STEM
B40: Fuel consumption in Services sectors | C40: Fuel consumption in services sectors by fuel and technology | D40: PJ/yr.
B41: Space water and process heat production in Services sectors | C41: Production of energy service demand for space, water and process heat in Services sectors | D41: PJ/yr.
B42: Efficiency in Services sectors | C42: Boilers efficiency and COP of heat pumps in the Services sectors | D42: %
...

Sheet SPS1
A1: Model | B1: Scenario | C1: Region | D1: Variable | E1: Unit | F1: 2020 | G1: 2022 | H1: 2025 | I1: 2030 | J1: 2035 | K1: 2040 | L1: 2045 | M1: 2050 | N1: 2055 | O1: 2060 | P1: 2065 | Q1: 2070
A2: STEM | B2: SPS1 | C2: CH | D2: Primary Production | E2: PJ/yr. | F2: =F3+F8+F11+F12+F16+F17+F18+F19 -> 299.98379 | G2: =G3+G8+G11+G12+G16+G17+G18+G19 -> 295.49195 | H2: =H3+H8+H11+H12+H16+H17+H18+H19 -> 331.44694 | I2: =I3+I8+I11+I12+I16+I17+I18+I19 -> 365.47345 | J2: =J3+J8+J11+J12+J16+J17+J18+J19 -> 376.67392 | K2: =K3+K8+K11+K12+K16+K17+K18+K19 -> 382.65095 | L2: =L3+L8+L11+L12+L16+L17+L18+L19 -> 387.50072 | M2: =M3+M8+M11+M12+M16+M17+M18+M19 -> 393.70485 | ... Q2: =Q3+Q8+Q11+Q12+Q16+Q17+Q18+Q19 -> 415.7712
A3: =A2 -> STEM | B3: =B2 -> SPS1 | C3: =C2 -> CH | D3: Primary Production|Wood | E3: PJ/yr. | F3: =SUM(F4:F7) -> 44.972403 | G3: =SUM(G4:G7) -> 48.190468 | H3: =SUM(H4:H7) -> 48.190469 | I3: =SUM(I4:I7) -> 48.19054 | J3: =SUM(J4:J7) -> 48.190996 | K3: =SUM(K4:K7) -> 48.190998 | L3: =SUM(L4:L7) -> 48.191 | M3: =SUM(M4:M7) -> 48.191003 | ... Q3: =SUM(Q4:Q7) -> 48.191049
A4: =A3 -> STEM | B4: =B3 -> SPS1 | C4: =C3 -> CH | D4: Primary Production|Wood|Waste wood | E4: PJ/yr. | F4: {=SUMPRODUCT(("RNWWOD1"=[1]OUT_PrimaryEnergyCons!$A$1:$A$1000)*1,[1]OUT_PrimaryEnergyCons!D$1:D$1000)} -> 11.111874 | G4: {=SUMPRODUCT(("RNWWOD1"=[1]OUT_PrimaryEnergyCons!$A$1:$A$1000)*1,[1]OUT_PrimaryEnergyCons!E$1:E$1000)} -> 11.952883 | H4: {=SUMPRODUCT(("RNWWOD1"=[1]OUT_PrimaryEnergyCons!$A$1:$A$1000)*1,[1]OUT_PrimaryEnergyCons!F$1:F$1000)} -> 13.214392 | I4: {=SUMPRODUCT(("RNWWOD1"=[1]OUT_PrimaryEnergyCons!$A$1:$A$1000)*1,[1]OUT_PrimaryEnergyCons!G$1:G$1000)} -> 15.31691 | J4: {=SUMPRODUCT(("RNWWOD1"=[1]OUT_PrimaryEnergyCons!$A$1:$A$1000)*1,[1]OUT_PrimaryEnergyCons!H$1:H$1000)} -> 15.849138 | K4: {=SUMPRODUCT(("RNWWOD1"=[1]OUT_PrimaryEnergyCons!$A$1:$A$1000)*1,[1]OUT_PrimaryEnergyCons!I$1:I$1000)} -> 16.266395 | L4: {=SUMPRODUCT(("RNWWOD1"=[1]OUT_PrimaryEnergyCons!$A$1:$A$1000)*1,[1]OUT_PrimaryEnergyCons!J$1:J$1000)} -> 16.611694 | M4: {=SUMPRODUCT(("RNWWOD1"=[1]OUT_PrimaryEnergyCons!$A$1:$A$1000)*1,[1]OUT_PrimaryEnergyCons!K$1:K$1000)} -> 16.956991 | ... Q4: {=SUMPRODUCT(("RNWWOD1"=[1]OUT_PrimaryEnergyCons!$A$1:$A$1000)*1,[1]OUT_PrimaryEnergyCons!O$1:O$1000)} -> 17.192059
A5: =A4 -> STEM | B5: =B4 -> SPS1 | C5: =C4 -> CH | D5: Primary Production|Wood|Wood residues | E5: PJ/yr. | F5: {=SUMPRODUCT(("RNWWOD2"=[1]OUT_PrimaryEnergyCons!$A$1:$A$1000)*1,[1]OUT_PrimaryEnergyCons!D$1:D$1000)} -> 7.5116673 | G5: {=SUMPRODUCT(("RNWWOD2"=[1]OUT_PrimaryEnergyCons!$A$1:$A$1000)*1,[1]OUT_PrimaryEnergyCons!E$1:E$1000)} -> 7.5431406 | H5: {=SUMPRODUCT(("RNWWOD2"=[1]OUT_PrimaryEnergyCons!$A$1:$A$1000)*1,[1]OUT_PrimaryEnergyCons!F$1:F$1000)} -> 7.5903468 | I5: {=SUMPRODUCT(("RNWWOD2"=[1]OUT_PrimaryEnergyCons!$A$1:$A$1000)*1,[1]OUT_PrimaryEnergyCons!G$1:G$1000)} -> 7.6690265 | J5: {=SUMPRODUCT(("RNWWOD2"=[1]OUT_PrimaryEnergyCons!$A$1:$A$1000)*1,[1]OUT_PrimaryEnergyCons!H$1:H$1000)} -> 7.6690253 | K5: {=SUMPRODUCT(("RNWWOD2"=[1]OUT_PrimaryEnergyCons!$A$1:$A$1000)*1,[1]OUT_PrimaryEnergyCons!I$1:I$1000)} -> 7.6690255 | L5: {=SUMPRODUCT(("RNWWOD2"=[1]OUT_PrimaryEnergyCons!$A$1:$A$1000)*1,[1]OUT_PrimaryEnergyCons!J$1:J$1000)} -> 7.6690256 | M5: {=SUMPRODUCT(("RNWWOD2"=[1]OUT_PrimaryEnergyCons!$A$1:$A$1000)*1,[1]OUT_PrimaryEnergyCons!K$1:K$1000)} -> 7.6690238 | ... Q5: {=SUMPRODUCT(("RNWWOD2"=[1]OUT_PrimaryEnergyCons!$A$1:$A$1000)*1,[1]OUT_PrimaryEnergyCons!O$1:O$1000)} -> 7.6690222
A6: =A5 -> STEM | B6: =B5 -> SPS1 | C6: =C5 -> CH | D6: Primary Production|Wood|Wood from landscape maintenance | E6: PJ/yr. | F6: {=SUMPRODUCT(("RNWWOD3"=[1]OUT_PrimaryEnergyCons!$A$1:$A$1000)*1,[1]OUT_PrimaryEnergyCons!D$1:D$1000)} -> 3.1682411 | G6: {=SUMPRODUCT(("RNWWOD3"=[1]OUT_PrimaryEnergyCons!$A$1:$A$1000)*1,[1]OUT_PrimaryEnergyCons!E$1:E$1000)} -> 3.4956719 | H6: {=SUMPRODUCT(("RNWWOD3"=[1]OUT_PrimaryEnergyCons!$A$1:$A$1000)*1,[1]OUT_PrimaryEnergyCons!F$1:F$1000)} -> 3.9868133 | I6: {=SUMPRODUCT(("RNWWOD3"=[1]OUT_PrimaryEnergyCons!$A$1:$A$1000)*1,[1]OUT_PrimaryEnergyCons!G$1:G$1000)} -> 4.8053859 | J6: {=SUMPRODUCT(("RNWWOD3"=[1]OUT_PrimaryEnergyCons!$A$1:$A$1000)*1,[1]OUT_PrimaryEnergyCons!H$1:H$1000)} -> 4.8053842 | K6: {=SUMPRODUCT(("RNWWOD3"=[1]OUT_PrimaryEnergyCons!$A$1:$A$1000)*1,[1]OUT_PrimaryEnergyCons!I$1:I$1000)} -> 4.8053844 | L6: {=SUMPRODUCT(("RNWWOD3"=[1]OUT_PrimaryEnergyCons!$A$1:$A$1000)*1,[1]OUT_PrimaryEnergyCons!J$1:J$1000)} -> 4.8053846 | M6: {=SUMPRODUCT(("RNWWOD3"=[1]OUT_PrimaryEnergyCons!$A$1:$A$1000)*1,[1]OUT_PrimaryEnergyCons!K$1:K$1000)} -> 4.805382 | ... Q6: {=SUMPRODUCT(("RNWWOD3"=[1]OUT_PrimaryEnergyCons!$A$1:$A$1000)*1,[1]OUT_PrimaryEnergyCons!O$1:O$1000)} -> 4.8053799
A7: =A6 -> STEM | B7: =B6 -> SPS1 | C7: =C6 -> CH | D7: Primary Production|Wood|Wood from Forest (hard wood) | E7: PJ/yr. | F7: {=SUMPRODUCT(("RNWWOD4"=[1]OUT_PrimaryEnergyCons!$A$1:$A$1000)*1+("RNWWOD5"=[1]OUT_PrimaryEnergyCons!$A$1:$A$1000)*1,[1]OUT_PrimaryEnergyCons!D$1:D$1000)} -> 23.18062 | G7: {=SUMPRODUCT(("RNWWOD4"=[1]OUT_PrimaryEnergyCons!$A$1:$A$1000)*1+("RNWWOD5"=[1]OUT_PrimaryEnergyCons!$A$1:$A$1000)*1,[1]OUT_PrimaryEnergyCons!E$1:E$1000)} -> 25.198772 | H7: {=SUMPRODUCT(("RNWWOD4"=[1]OUT_PrimaryEnergyCons!$A$1:$A$1000)*1+("RNWWOD5"=[1]OUT_PrimaryEnergyCons!$A$1:$A$1000)*1,[1]OUT_PrimaryEnergyCons!F$1:F$1000)} -> 23.398917 | I7: {=SUMPRODUCT(("RNWWOD4"=[1]OUT_PrimaryEnergyCons!$A$1:$A$1000)*1+("RNWWOD5"=[1]OUT_PrimaryEnergyCons!$A$1:$A$1000)*1,[1]OUT_PrimaryEnergyCons!G$1:G$1000)} -> 20.399218 | J7: {=SUMPRODUCT(("RNWWOD4"=[1]OUT_PrimaryEnergyCons!$A$1:$A$1000)*1+("RNWWOD5"=[1]OUT_PrimaryEnergyCons!$A$1:$A$1000)*1,[1]OUT_PrimaryEnergyCons!H$1:H$1000)} -> 19.867448 | K7: {=SUMPRODUCT(("RNWWOD4"=[1]OUT_PrimaryEnergyCons!$A$1:$A$1000)*1+("RNWWOD5"=[1]OUT_PrimaryEnergyCons!$A$1:$A$1000)*1,[1]OUT_PrimaryEnergyCons!I$1:I$1000)} -> 19.450193 | L7: {=SUMPRODUCT(("RNWWOD4"=[1]OUT_PrimaryEnergyCons!$A$1:$A$1000)*1+("RNWWOD5"=[1]OUT_PrimaryEnergyCons!$A$1:$A$1000)*1,[1]OUT_PrimaryEnergyCons!J$1:J$1000)} -> 19.104895 | M7: {=SUMPRODUCT(("RNWWOD4"=[1]OUT_PrimaryEnergyCons!$A$1:$A$1000)*1+("RNWWOD5"=[1]OUT_PrimaryEnergyCons!$A$1:$A$1000)*1,[1]OUT_PrimaryEnergyCons!K$1:K$1000)} -> 18.759606 | ... Q7: {=SUMPRODUCT(("RNWWOD4"=[1]OUT_PrimaryEnergyCons!$A$1:$A$1000)*1+("RNWWOD5"=[1]OUT_PrimaryEnergyCons!$A$1:$A$1000)*1,[1]OUT_PrimaryEnergyCons!O$1:O$1000)} -> 18.524587
A8: =A7 -> STEM | B8: =B7 -> SPS1 | C8: =C7 -> CH | D8: Primary Production|Waste | E8: PJ/yr. | F8: =SUM(F9:F10) -> 69.829366 | G8: =SUM(G9:G10) -> 69.881741 | H8: =SUM(H9:H10) -> 69.488904 | I8: =SUM(I9:I10) -> 69.039323 | J8: =SUM(J9:J10) -> 68.937026 | K8: =SUM(K9:K10) -> 69.158804 | L8: =SUM(L9:L10) -> 69.38067 | M8: =SUM(M9:M10) -> 69.602628 | ... Q8: =SUM(Q9:Q10) -> 69.602689
A9: =A8 -> STEM | B9: =B8 -> SPS1 | C9: =C8 -> CH | D9: Primary Production|Waste|Non renewable waste | E9: PJ/yr. | F9: {=SUMPRODUCT(("RNNWWST1"=[1]OUT_PrimaryEnergyCons!$A$1:$A$1000)*1,[1]OUT_PrimaryEnergyCons!D$1:D$1000)} -> 35.830007 | G9: {=SUMPRODUCT(("RNNWWST1"=[1]OUT_PrimaryEnergyCons!$A$1:$A$1000)*1,[1]OUT_PrimaryEnergyCons!E$1:E$1000)} -> 35.882383 | H9: {=SUMPRODUCT(("RNNWWST1"=[1]OUT_PrimaryEnergyCons!$A$1:$A$1000)*1,[1]OUT_PrimaryEnergyCons!F$1:F$1000)} -> 35.489461 | I9: {=SUMPRODUCT(("RNNWWST1"=[1]OUT_PrimaryEnergyCons!$A$1:$A$1000)*1,[1]OUT_PrimaryEnergyCons!G$1:G$1000)} -> 35.039968 | J9: {=SUMPRODUCT(("RNNWWST1"=[1]OUT_PrimaryEnergyCons!$A$1:$A$1000)*1,[1]OUT_PrimaryEnergyCons!H$1:H$1000)} -> 34.937586 | K9: {=SUMPRODUCT(("RNNWWST1"=[1]OUT_PrimaryEnergyCons!$A$1:$A$1000)*1,[1]OUT_PrimaryEnergyCons!I$1:I$1000)} -> 35.159449 | L9: {=SUMPRODUCT(("RNNWWST1"=[1]OUT_PrimaryEnergyCons!$A$1:$A$1000)*1,[1]OUT_PrimaryEnergyCons!J$1:J$1000)} -> 35.381314 | M9: {=SUMPRODUCT(("RNNWWST1"=[1]OUT_PrimaryEnergyCons!$A$1:$A$1000)*1,[1]OUT_PrimaryEnergyCons!K$1:K$1000)} -> 35.603181 | ... Q9: {=SUMPRODUCT(("RNNWWST1"=[1]OUT_PrimaryEnergyCons!$A$1:$A$1000)*1,[1]OUT_PrimaryEnergyCons!O$1:O$1000)} -> 35.603184
A10: =A9 -> STEM | B10: =B9 -> SPS1 | C10: =C9 -> CH | D10: Primary Production|Waste|Renewable waste | E10: PJ/yr. | F10: {=SUMPRODUCT(("RNWWST1"=[1]OUT_PrimaryEnergyCons!$A$1:$A$1000)*1,[1]OUT_PrimaryEnergyCons!D$1:D$1000)} -> 33.999359 | G10: {=SUMPRODUCT(("RNWWST1"=[1]OUT_PrimaryEnergyCons!$A$1:$A$1000)*1,[1]OUT_PrimaryEnergyCons!E$1:E$1000)} -> 33.999358 | H10: {=SUMPRODUCT(("RNWWST1"=[1]OUT_PrimaryEnergyCons!$A$1:$A$1000)*1,[1]OUT_PrimaryEnergyCons!F$1:F$1000)} -> 33.999443 | I10: {=SUMPRODUCT(("RNWWST1"=[1]OUT_PrimaryEnergyCons!$A$1:$A$1000)*1,[1]OUT_PrimaryEnergyCons!G$1:G$1000)} -> 33.999355 | J10: {=SUMPRODUCT(("RNWWST1"=[1]OUT_PrimaryEnergyCons!$A$1:$A$1000)*1,[1]OUT_PrimaryEnergyCons!H$1:H$1000)} -> 33.99944 | K10: {=SUMPRODUCT(("RNWWST1"=[1]OUT_PrimaryEnergyCons!$A$1:$A$1000)*1,[1]OUT_PrimaryEnergyCons!I$1:I$1000)} -> 33.999354 | L10: {=SUMPRODUCT(("RNWWST1"=[1]OUT_PrimaryEnergyCons!$A$1:$A$1000)*1,[1]OUT_PrimaryEnergyCons!J$1:J$1000)} -> 33.999356 | M10: {=SUMPRODUCT(("RNWWST1"=[1]OUT_PrimaryEnergyCons!$A$1:$A$1000)*1,[1]OUT_PrimaryEnergyCons!K$1:K$1000)} -> 33.999446 | ... Q10: {=SUMPRODUCT(("RNWWST1"=[1]OUT_PrimaryEnergyCons!$A$1:$A$1000)*1,[1]OUT_PrimaryEnergyCons!O$1:O$1000)} -> 33.999505
A11: =A10 -> STEM | B11: =B10 -> SPS1 | C11: =C10 -> CH | D11: Primary Production|Manure | E11: PJ/yr. | F11: {=SUMPRODUCT(("mnr"=[1]OUT_PrimaryEnergyCons!$C$1:$C$1000)*1,[1]OUT_PrimaryEnergyCons!D$1:D$1000)} -> 3.798083 | G11: {=SUMPRODUCT(("mnr"=[1]OUT_PrimaryEnergyCons!$C$1:$C$1000)*1,[1]OUT_PrimaryEnergyCons!E$1:E$1000)} -> 12.531647 | H11: {=SUMPRODUCT(("mnr"=[1]OUT_PrimaryEnergyCons!$C$1:$C$1000)*1,[1]OUT_PrimaryEnergyCons!F$1:F$1000)} -> 12.540332 | I11: {=SUMPRODUCT(("mnr"=[1]OUT_PrimaryEnergyCons!$C$1:$C$1000)*1,[1]OUT_PrimaryEnergyCons!G$1:G$1000)} -> 12.540424 | J11: {=SUMPRODUCT(("mnr"=[1]OUT_PrimaryEnergyCons!$C$1:$C$1000)*1,[1]OUT_PrimaryEnergyCons!H$1:H$1000)} -> 12.540426 | K11: {=SUMPRODUCT(("mnr"=[1]OUT_PrimaryEnergyCons!$C$1:$C$1000)*1,[1]OUT_PrimaryEnergyCons!I$1:I$1000)} -> 12.541342 | L11: {=SUMPRODUCT(("mnr"=[1]OUT_PrimaryEnergyCons!$C$1:$C$1000)*1,[1]OUT_PrimaryEnergyCons!J$1:J$1000)} -> 12.541363 | M11: {=SUMPRODUCT(("mnr"=[1]OUT_PrimaryEnergyCons!$C$1:$C$1000)*1,[1]OUT_PrimaryEnergyCons!K$1:K$1000)} -> 12.541388 | ... Q11: {=SUMPRODUCT(("mnr"=[1]OUT_PrimaryEnergyCons!$C$1:$C$1000)*1,[1]OUT_PrimaryEnergyCons!O$1:O$1000)} -> 12.541635
A12: =A11 -> STEM | B12: =B11 -> SPS1 | C12: =C11 -> CH | D12: Primary Production|Hydro | E12: PJ/yr. | F12: =SUM(F13:F15) -> 149.43048 | G12: =SUM(G13:G15) -> 125.60576 | H12: =SUM(H13:H15) -> 141.96163 | I12: =SUM(I13:I15) -> 150.00947 | J12: =SUM(J13:J15) -> 150.0561 | K12: =SUM(K13:K15) -> 150.09411 | L12: =SUM(L13:L15) -> 150.13197 | M12: =SUM(M13:M15) -> 150.17255 | ... Q12: =SUM(Q13:Q15) -> 150.77481
A13: =A12 -> STEM | B13: =B12 -> SPS1 | C13: =C12 -> CH | D13: Primary Production|Hydro|Large hydro | E13: PJ/yr. | F13: {=SUMPRODUCT(ISNUMBER(SEARCH("EHYD-DAM",[1]OUT_Electricity_CHP!$B$1:$B$10000))*1,([1]OUT_Electricity_CHP!$C$1:$C$10000="Var_Fout")*1,ISNUMBER(SEARCH("ELC",[1]OUT_Electricity_CHP!$D$1:$D$10000))*1,[1]OUT_Electricity_CHP!E$1:E$10000)} -> 66.74568 | G13: {=SUMPRODUCT(ISNUMBER(SEARCH("EHYD-DAM",[1]OUT_Electricity_CHP!$B$1:$B$10000))*1,([1]OUT_Electricity_CHP!$C$1:$C$10000="Var_Fout")*1,ISNUMBER(SEARCH("ELC",[1]OUT_Electricity_CHP!$D$1:$D$10000))*1,[1]OUT_Electricity_CHP!F$1:F$10000)} -> 49.798809 | H13: {=SUMPRODUCT(ISNUMBER(SEARCH("EHYD-DAM",[1]OUT_Electricity_CHP!$B$1:$B$10000))*1,([1]OUT_Electricity_CHP!$C$1:$C$10000="Var_Fout")*1,ISNUMBER(SEARCH("ELC",[1]OUT_Electricity_CHP!$D$1:$D$10000))*1,[1]OUT_Electricity_CHP!G$1:G$10000)} -> 68.535331 | I13: {=SUMPRODUCT(ISNUMBER(SEARCH("EHYD-DAM",[1]OUT_Electricity_CHP!$B$1:$B$10000))*1,([1]OUT_Electricity_CHP!$C$1:$C$10000="Var_Fout")*1,ISNUMBER(SEARCH("ELC",[1]OUT_Electricity_CHP!$D$1:$D$10000))*1,[1]OUT_Electricity_CHP!H$1:H$10000)} -> 69.618852 | J13: {=SUMPRODUCT(ISNUMBER(SEARCH("EHYD-DAM",[1]OUT_Electricity_CHP!$B$1:$B$10000))*1,([1]OUT_Electricity_CHP!$C$1:$C$10000="Var_Fout")*1,ISNUMBER(SEARCH("ELC",[1]OUT_Electricity_CHP!$D$1:$D$10000))*1,[1]OUT_Electricity_CHP!I$1:I$10000)} -> 70.703295 | K13: {=SUMPRODUCT(ISNUMBER(SEARCH("EHYD-DAM",[1]OUT_Electricity_CHP!$B$1:$B$10000))*1,([1]OUT_Electricity_CHP!$C$1:$C$10000="Var_Fout")*1,ISNUMBER(SEARCH("ELC",[1]OUT_Electricity_CHP!$D$1:$D$10000))*1,[1]OUT_Electricity_CHP!J$1:J$10000)} -> 71.78804 | L13: {=SUMPRODUCT(ISNUMBER(SEARCH("EHYD-DAM",[1]OUT_Electricity_CHP!$B$1:$B$10000))*1,([1]OUT_Electricity_CHP!$C$1:$C$10000="Var_Fout")*1,ISNUMBER(SEARCH("ELC",[1]OUT_Electricity_CHP!$D$1:$D$10000))*1,[1]OUT_Electricity_CHP!K$1:K$10000)} -> 72.872456 | M13: {=SUMPRODUCT(ISNUMBER(SEARCH("EHYD-DAM",[1]OUT_Electricity_CHP!$B$1:$B$10000))*1,([1]OUT_Electricity_CHP!$C$1:$C$10000="Var_Fout")*1,ISNUMBER(SEARCH("ELC",[1]OUT_Electricity_CHP!$D$1:$D$10000))*1,[1]OUT_Electricity_CHP!L$1:L$10000)} -> 73.957468 | ... Q13: {=SUMPRODUCT(ISNUMBER(SEARCH("EHYD-DAM",[1]OUT_Electricity_CHP!$B$1:$B$10000))*1,([1]OUT_Electricity_CHP!$C$1:$C$10000="Var_Fout")*1,ISNUMBER(SEARCH("ELC",[1]OUT_Electricity_CHP!$D$1:$D$10000))*1,[1]OUT_Electricity_CHP!P$1:P$10000)} -> 73.957069
A14: =A13 -> STEM | B14: =B13 -> SPS1 | C14: =C13 -> CH | D14: Primary Production|Hydro|Run-of-river hydro | E14: PJ/yr. | F14: {=SUMPRODUCT(ISNUMBER(SEARCH("EHYD-RUN",[1]OUT_Electricity_CHP!$B$1:$B$10000))*1,([1]OUT_Electricity_CHP!$C$1:$C$10000="Var_Fout")*1,ISNUMBER(SEARCH("ELC",[1]OUT_Electricity_CHP!$D$1:$D$10000))*1,[1]OUT_Electricity_CHP!E$1:E$10000)} -> 66.6324 | G14: {=SUMPRODUCT(ISNUMBER(SEARCH("EHYD-RUN",[1]OUT_Electricity_CHP!$B$1:$B$10000))*1,([1]OUT_Electricity_CHP!$C$1:$C$10000="Var_Fout")*1,ISNUMBER(SEARCH("ELC",[1]OUT_Electricity_CHP!$D$1:$D$10000))*1,[1]OUT_Electricity_CHP!F$1:F$10000)} -> 55.76401 | H14: {=SUMPRODUCT(ISNUMBER(SEARCH("EHYD-RUN",[1]OUT_Electricity_CHP!$B$1:$B$10000))*1,([1]OUT_Electricity_CHP!$C$1:$C$10000="Var_Fout")*1,ISNUMBER(SEARCH("ELC",[1]OUT_Electricity_CHP!$D$1:$D$10000))*1,[1]OUT_Electricity_CHP!G$1:G$10000)} -> 65.550673 | I14: {=SUMPRODUCT(ISNUMBER(SEARCH("EHYD-RUN",[1]OUT_Electricity_CHP!$B$1:$B$10000))*1,([1]OUT_Electricity_CHP!$C$1:$C$10000="Var_Fout")*1,ISNUMBER(SEARCH("ELC",[1]OUT_Electricity_CHP!$D$1:$D$10000))*1,[1]OUT_Electricity_CHP!H$1:H$10000)} -> 64.467168 | J14: {=SUMPRODUCT(ISNUMBER(SEARCH("EHYD-RUN",[1]OUT_Electricity_CHP!$B$1:$B$10000))*1,([1]OUT_Electricity_CHP!$C$1:$C$10000="Var_Fout")*1,ISNUMBER(SEARCH("ELC",[1]OUT_Electricity_CHP!$D$1:$D$10000))*1,[1]OUT_Electricity_CHP!I$1:I$10000)} -> 63.382752 | K14: {=SUMPRODUCT(ISNUMBER(SEARCH("EHYD-RUN",[1]OUT_Electricity_CHP!$B$1:$B$10000))*1,([1]OUT_Electricity_CHP!$C$1:$C$10000="Var_Fout")*1,ISNUMBER(SEARCH("ELC",[1]OUT_Electricity_CHP!$D$1:$D$10000))*1,[1]OUT_Electricity_CHP!J$1:J$10000)} -> 62.298008 | L14: {=SUMPRODUCT(ISNUMBER(SEARCH("EHYD-RUN",[1]OUT_Electricity_CHP!$B$1:$B$10000))*1,([1]OUT_Electricity_CHP!$C$1:$C$10000="Var_Fout")*1,ISNUMBER(SEARCH("ELC",[1]OUT_Electricity_CHP!$D$1:$D$10000))*1,[1]OUT_Electricity_CHP!K$1:K$10000)} -> 61.213593 | M14: {=SUMPRODUCT(ISNUMBER(SEARCH("EHYD-RUN",[1]OUT_Electricity_CHP!$B$1:$B$10000))*1,([1]OUT_Electricity_CHP!$C$1:$C$10000="Var_Fout")*1,ISNUMBER(SEARCH("ELC",[1]OUT_Electricity_CHP!$D$1:$D$10000))*1,[1]OUT_Electricity_CHP!L$1:L$10000)} -> 60.128581 | ... Q14: {=SUMPRODUCT(ISNUMBER(SEARCH("EHYD-RUN",[1]OUT_Electricity_CHP!$B$1:$B$10000))*1,([1]OUT_Electricity_CHP!$C$1:$C$10000="Var_Fout")*1,ISNUMBER(SEARCH("ELC",[1]OUT_Electricity_CHP!$D$1:$D$10000))*1,[1]OUT_Electricity_CHP!P$1:P$10000)} -> 60.129
A15: =A14 -> STEM | B15: =B14 -> SPS1 | C15: =C14 -> CH | D15: Primary Production|Hydro|Pump storage | E15: PJ/yr. | F15: {=SUMPRODUCT(ISNUMBER(SEARCH("EHYD-PUM",[1]OUT_Electricity_CHP!$B$1:$B$10000))*1,([1]OUT_Electricity_CHP!$C$1:$C$10000="Var_Fin")*1,ISNUMBER(SEARCH("elc",[1]OUT_Electricity_CHP!$D$1:$D$10000))*1,[1]OUT_Electricity_CHP!E$1:E$10000)} -> 16.052401 | G15: {=SUMPRODUCT(ISNUMBER(SEARCH("EHYD-PUM",[1]OUT_Electricity_CHP!$B$1:$B$10000))*1,([1]OUT_Electricity_CHP!$C$1:$C$10000="Var_Fin")*1,ISNUMBER(SEARCH("elc",[1]OUT_Electricity_CHP!$D$1:$D$10000))*1,[1]OUT_Electricity_CHP!F$1:F$10000)} -> 20.042942 | H15: {=SUMPRODUCT(ISNUMBER(SEARCH("EHYD-PUM",[1]OUT_Electricity_CHP!$B$1:$B$10000))*1,([1]OUT_Electricity_CHP!$C$1:$C$10000="Var_Fin")*1,ISNUMBER(SEARCH("elc",[1]OUT_Electricity_CHP!$D$1:$D$10000))*1,[1]OUT_Electricity_CHP!G$1:G$10000)} -> 7.875622 | I15: {=SUMPRODUCT(ISNUMBER(SEARCH("EHYD-PUM",[1]OUT_Electricity_CHP!$B$1:$B$10000))*1,([1]OUT_Electricity_CHP!$C$1:$C$10000="Var_Fin")*1,ISNUMBER(SEARCH("elc",[1]OUT_Electricity_CHP!$D$1:$D$10000))*1,[1]OUT_Electricity_CHP!H$1:H$10000)} -> 15.923445 | J15: {=SUMPRODUCT(ISNUMBER(SEARCH("EHYD-PUM",[1]OUT_Electricity_CHP!$B$1:$B$10000))*1,([1]OUT_Electricity_CHP!$C$1:$C$10000="Var_Fin")*1,ISNUMBER(SEARCH("elc",[1]OUT_Electricity_CHP!$D$1:$D$10000))*1,[1]OUT_Electricity_CHP!I$1:I$10000)} -> 15.970051 | K15: {=SUMPRODUCT(ISNUMBER(SEARCH("EHYD-PUM",[1]OUT_Electricity_CHP!$B$1:$B$10000))*1,([1]OUT_Electricity_CHP!$C$1:$C$10000="Var_Fin")*1,ISNUMBER(SEARCH("elc",[1]OUT_Electricity_CHP!$D$1:$D$10000))*1,[1]OUT_Electricity_CHP!J$1:J$10000)} -> 16.008058 | L15: {=SUMPRODUCT(ISNUMBER(SEARCH("EHYD-PUM",[1]OUT_Electricity_CHP!$B$1:$B$10000))*1,([1]OUT_Electricity_CHP!$C$1:$C$10000="Var_Fin")*1,ISNUMBER(SEARCH("elc",[1]OUT_Electricity_CHP!$D$1:$D$10000))*1,[1]OUT_Electricity_CHP!K$1:K$10000)} -> 16.045926 | M15: {=SUMPRODUCT(ISNUMBER(SEARCH("EHYD-PUM",[1]OUT_Electricity_CHP!$B$1:$B$10000))*1,([1]OUT_Electricity_CHP!$C$1:$C$10000="Var_Fin")*1,ISNUMBER(SEARCH("elc",[1]OUT_Electricity_CHP!$D$1:$D$10000))*1,[1]OUT_Electricity_CHP!L$1:L$10000)} -> 16.086498 | ... Q15: {=SUMPRODUCT(ISNUMBER(SEARCH("EHYD-PUM",[1]OUT_Electricity_CHP!$B$1:$B$10000))*1,([1]OUT_Electricity_CHP!$C$1:$C$10000="Var_Fin")*1,ISNUMBER(SEARCH("elc",[1]OUT_Electricity_CHP!$D$1:$D$10000))*1,[1]OUT_Electricity_CHP!P$1:P$10000)} -> 16.688738
A16: =A15 -> STEM | B16: =B15 -> SPS1 | C16: =C15 -> CH | D16: Primary Production|Solar | E16: PJ/yr. | F16: {=SUMPRODUCT(ISNUMBER(SEARCH("SOL",[1]OUT_PrimaryEnergyCons!$C$1:$C$1000))*1,[1]OUT_PrimaryEnergyCons!D$1:D$1000)} -> 12.556448 | G16: {=SUMPRODUCT(ISNUMBER(SEARCH("SOL",[1]OUT_PrimaryEnergyCons!$C$1:$C$1000))*1,[1]OUT_PrimaryEnergyCons!E$1:E$1000)} -> 16.522198 | H16: {=SUMPRODUCT(ISNUMBER(SEARCH("SOL",[1]OUT_PrimaryEnergyCons!$C$1:$C$1000))*1,[1]OUT_PrimaryEnergyCons!F$1:F$1000)} -> 32.458996 | I16: {=SUMPRODUCT(ISNUMBER(SEARCH("SOL",[1]OUT_PrimaryEnergyCons!$C$1:$C$1000))*1,[1]OUT_PrimaryEnergyCons!G$1:G$1000)} -> 54.379022 | J16: {=SUMPRODUCT(ISNUMBER(SEARCH("SOL",[1]OUT_PrimaryEnergyCons!$C$1:$C$1000))*1,[1]OUT_PrimaryEnergyCons!H$1:H$1000)} -> 57.311467 | K16: {=SUMPRODUCT(ISNUMBER(SEARCH("SOL",[1]OUT_PrimaryEnergyCons!$C$1:$C$1000))*1,[1]OUT_PrimaryEnergyCons!I$1:I$1000)} -> 59.963837 | L16: {=SUMPRODUCT(ISNUMBER(SEARCH("SOL",[1]OUT_PrimaryEnergyCons!$C$1:$C$1000))*1,[1]OUT_PrimaryEnergyCons!J$1:J$1000)} -> 62.675842 | M16: {=SUMPRODUCT(ISNUMBER(SEARCH("SOL",[1]OUT_PrimaryEnergyCons!$C$1:$C$1000))*1,[1]OUT_PrimaryEnergyCons!K$1:K$1000)} -> 65.425713 | ... Q16: {=SUMPRODUCT(ISNUMBER(SEARCH("SOL",[1]OUT_PrimaryEnergyCons!$C$1:$C$1000))*1,[1]OUT_PrimaryEnergyCons!O$1:O$1000)} -> 78.060877
A17: =A16 -> STEM | B17: =B16 -> SPS1 | C17: =C16 -> CH | D17: Primary Production|Wind | E17: PJ/yr. | F17: {=SUMPRODUCT(ISNUMBER(SEARCH("wnd",[1]OUT_PrimaryEnergyCons!$C$1:$C$1000))*1,[1]OUT_PrimaryEnergyCons!D$1:D$1000)} -> 0.52400509 | G17: {=SUMPRODUCT(ISNUMBER(SEARCH("wnd",[1]OUT_PrimaryEnergyCons!$C$1:$C$1000))*1,[1]OUT_PrimaryEnergyCons!E$1:E$1000)} -> 0.54529604 | H17: {=SUMPRODUCT(ISNUMBER(SEARCH("wnd",[1]OUT_PrimaryEnergyCons!$C$1:$C$1000))*1,[1]OUT_PrimaryEnergyCons!F$1:F$1000)} -> 0.50316911 | I17: {=SUMPRODUCT(ISNUMBER(SEARCH("wnd",[1]OUT_PrimaryEnergyCons!$C$1:$C$1000))*1,[1]OUT_PrimaryEnergyCons!G$1:G$1000)} -> 0.54633238 | J17: {=SUMPRODUCT(ISNUMBER(SEARCH("wnd",[1]OUT_PrimaryEnergyCons!$C$1:$C$1000))*1,[1]OUT_PrimaryEnergyCons!H$1:H$1000)} -> 0.54692006 | K17: {=SUMPRODUCT(ISNUMBER(SEARCH("wnd",[1]OUT_PrimaryEnergyCons!$C$1:$C$1000))*1,[1]OUT_PrimaryEnergyCons!I$1:I$1000)} -> 0.54701718 | L17: {=SUMPRODUCT(ISNUMBER(SEARCH("wnd",[1]OUT_PrimaryEnergyCons!$C$1:$C$1000))*1,[1]OUT_PrimaryEnergyCons!J$1:J$1000)} -> 0.55240939 | M17: {=SUMPRODUCT(ISNUMBER(SEARCH("wnd",[1]OUT_PrimaryEnergyCons!$C$1:$C$1000))*1,[1]OUT_PrimaryEnergyCons!K$1:K$1000)} -> 0.5525237 | ... Q17: {=SUMPRODUCT(ISNUMBER(SEARCH("wnd",[1]OUT_PrimaryEnergyCons!$C$1:$C$1000))*1,[1]OUT_PrimaryEnergyCons!O$1:O$1000)} -> 0.55530369
A18: =A17 -> STEM | B18: =B17 -> SPS1 | C18: =C17 -> CH | D18: Primary Production|Ambient heat | E18: PJ/yr. | F18: =[1]Overview!B$9-F19 -> 18.873007 | G18: =[1]Overview!C$9-G19 -> 22.214843 | H18: =[1]Overview!D$9-H19 -> 26.303443 | I18: =[1]Overview!E$9-I19 -> 30.768344 | J18: =[1]Overview!F$9-J19 -> 39.090984 | K18: =[1]Overview!G$9-K19 -> 42.154583 | L18: =[1]Overview!H$9-L19 -> 43.997846 | M18: =[1]Overview!I$9-M19 -> 47.158587 | ... Q18: =[1]Overview!M$9-Q19 -> 56.044841
A19: =A18 -> STEM | B19: =B18 -> SPS1 | C19: =C18 -> CH | D19: Primary Production|Geothermal | E19: PJ/yr. | F19: =+[1]Overview!B$28 -> 0 | G19: =+[1]Overview!C$28 -> 0 | H19: =+[1]Overview!D$28 -> 0 | I19: =+[1]Overview!E$28 -> 0 | J19: =+[1]Overview!F$28 -> 0 | K19: =+[1]Overview!G$28 -> 0.0002623354 | L19: =+[1]Overview!H$28 -> 0.029612124 | M19: =+[1]Overview!I$28 -> 0.060464531 | ... Q19: =+[1]Overview!M$28 -> 0
A20: =A19 -> STEM | B20: =B19 -> SPS1 | C20: =C19 -> CH | D20: Imports | E20: PJ/yr. | F20: =SUM(F21:F22,F41,F50:F51,F56) -> 779.55394 | G20: =SUM(G21:G22,G41,G50:G51,G56) -> 702.62669 | H20: =SUM(H21:H22,H41,H50:H51,H56) -> 657.4738 | I20: =SUM(I21:I22,I41,I50:I51,I56) -> 613.5139 | J20: =SUM(J21:J22,J41,J50:J51,J56) -> 523.94075 | K20: =SUM(K21:K22,K41,K50:K51,K56) -> 436.22267 | L20: =SUM(L21:L22,L41,L50:L51,L56) -> 330.44045 | M20: =SUM(M21:M22,M41,M50:M51,M56) -> 312.77658 | ... Q20: =SUM(Q21:Q22,Q41,Q50:Q51,Q56) -> 293.03084
A21: =A20 -> STEM | B21: =B20 -> SPS1 | C21: =C20 -> CH | D21: Imports|Coal | E21: PJ/yr. | F21: {=SUMPRODUCT(("COA"=[1]OUT_PrimaryEnergyCons!$C$4:$C$10000)*1,[1]OUT_PrimaryEnergyCons!D$4:D$10000)} -> 3.6600036 | G21: {=SUMPRODUCT(("COA"=[1]OUT_PrimaryEnergyCons!$C$4:$C$10000)*1,[1]OUT_PrimaryEnergyCons!E$4:E$10000)} -> 3.5647187 | H21: {=SUMPRODUCT(("COA"=[1]OUT_PrimaryEnergyCons!$C$4:$C$10000)*1,[1]OUT_PrimaryEnergyCons!F$4:F$10000)} -> 2.8413068 | I21: {=SUMPRODUCT(("COA"=[1]OUT_PrimaryEnergyCons!$C$4:$C$10000)*1,[1]OUT_PrimaryEnergyCons!G$4:G$10000)} -> 0.0024908497 | J21: {=SUMPRODUCT(("COA"=[1]OUT_PrimaryEnergyCons!$C$4:$C$10000)*1,[1]OUT_PrimaryEnergyCons!H$4:H$10000)} -> 0.0017932378 | K21: {=SUMPRODUCT(("COA"=[1]OUT_PrimaryEnergyCons!$C$4:$C$10000)*1,[1]OUT_PrimaryEnergyCons!I$4:I$10000)} -> 0.0010643396 | L21: {=SUMPRODUCT(("COA"=[1]OUT_PrimaryEnergyCons!$C$4:$C$10000)*1,[1]OUT_PrimaryEnergyCons!J$4:J$10000)} -> 0.0013485759 | M21: {=SUMPRODUCT(("COA"=[1]OUT_PrimaryEnergyCons!$C$4:$C$10000)*1,[1]OUT_PrimaryEnergyCons!K$4:K$10000)} -> 0.003013073 | ... Q21: {=SUMPRODUCT(("COA"=[1]OUT_PrimaryEnergyCons!$C$4:$C$10000)*1,[1]OUT_PrimaryEnergyCons!O$4:O$10000)} -> 0.0030893599
A22: =A21 -> STEM | B22: =B21 -> SPS1 | C22: =C21 -> CH | D22: Imports|Oil | E22: PJ/yr. | F22: =F23+F29 -> 310.79199 | G22: =G23+G29 -> 287.15785 | H22: =H23+H29 -> 266.58574 | I22: =I23+I29 -> 219.90021 | J22: =J23+J29 -> 167.50891 | K22: =K23+K29 -> 148.41194 | L22: =L23+L29 -> 135.62976 | M22: =M23+M29 -> 122.3012 | ... Q22: =Q23+Q29 -> 66.960989
A23: =A22 -> STEM | B23: =B22 -> SPS1 | C23: =C22 -> CH | D23: Imports|Oil|Fossil liquids | E23: PJ/yr. | F23: =SUM(F24:F28) -> 303.95694 | G23: =SUM(G24:G28) -> 280.38122 | H23: =SUM(H24:H28) -> 258.04245 | I23: =SUM(I24:I28) -> 206.97651 | J23: =SUM(J24:J28) -> 155.85139 | K23: =SUM(K24:K28) -> 137.22312 | L23: =SUM(L24:L28) -> 124.61024 | M23: =SUM(M24:M28) -> 111.42296 | ... Q23: =SUM(Q24:Q28) -> 58.970139
A24: =A22 -> STEM | B24: =B22 -> SPS1 | C24: =C22 -> CH | D24: Imports|Oil|Fossil liquids|Light fuel oil | E24: PJ/yr. | F24: {=SUMPRODUCT(("LFO"=[1]OUT_PrimaryEnergyCons!$C$4:$C$10000)*1,[1]OUT_PrimaryEnergyCons!D$4:D$10000)} -> 101.73551 | G24: {=SUMPRODUCT(("LFO"=[1]OUT_PrimaryEnergyCons!$C$4:$C$10000)*1,[1]OUT_PrimaryEnergyCons!E$4:E$10000)} -> 88.823145 | H24: {=SUMPRODUCT(("LFO"=[1]OUT_PrimaryEnergyCons!$C$4:$C$10000)*1,[1]OUT_PrimaryEnergyCons!F$4:F$10000)} -> 79.5 | I24: {=SUMPRODUCT(("LFO"=[1]OUT_PrimaryEnergyCons!$C$4:$C$10000)*1,[1]OUT_PrimaryEnergyCons!G$4:G$10000)} -> 75.590877 | J24: {=SUMPRODUCT(("LFO"=[1]OUT_PrimaryEnergyCons!$C$4:$C$10000)*1,[1]OUT_PrimaryEnergyCons!H$4:H$10000)} -> 60.448903 | K24: {=SUMPRODUCT(("LFO"=[1]OUT_PrimaryEnergyCons!$C$4:$C$10000)*1,[1]OUT_PrimaryEnergyCons!I$4:I$10000)} -> 52.289041 | L24: {=SUMPRODUCT(("LFO"=[1]OUT_PrimaryEnergyCons!$C$4:$C$10000)*1,[1]OUT_PrimaryEnergyCons!J$4:J$10000)} -> 48.478068 | M24: {=SUMPRODUCT(("LFO"=[1]OUT_PrimaryEnergyCons!$C$4:$C$10000)*1,[1]OUT_PrimaryEnergyCons!K$4:K$10000)} -> 41.935001 | ... Q24: {=SUMPRODUCT(("LFO"=[1]OUT_PrimaryEnergyCons!$C$4:$C$10000)*1,[1]OUT_PrimaryEnergyCons!O$4:O$10000)} -> 8.3699938
A25: =A24 -> STEM | B25: =B24 -> SPS1 | C25: =C24 -> CH | D25: Imports|Oil|Fossil liquids|Heavy fuel oil | E25: PJ/yr. | F25: {=SUMPRODUCT(("HFO"=[1]OUT_PrimaryEnergyCons!$C$4:$C$10000)*1,[1]OUT_PrimaryEnergyCons!D$4:D$10000)} -> 2.7763697 | G25: {=SUMPRODUCT(("HFO"=[1]OUT_PrimaryEnergyCons!$C$4:$C$10000)*1,[1]OUT_PrimaryEnergyCons!E$4:E$10000)} -> 2.1548464 | H25: {=SUMPRODUCT(("HFO"=[1]OUT_PrimaryEnergyCons!$C$4:$C$10000)*1,[1]OUT_PrimaryEnergyCons!F$4:F$10000)} -> 0.0026316917 | I25: {=SUMPRODUCT(("HFO"=[1]OUT_PrimaryEnergyCons!$C$4:$C$10000)*1,[1]OUT_PrimaryEnergyCons!G$4:G$10000)} -> 0.00075746549 | J25: {=SUMPRODUCT(("HFO"=[1]OUT_PrimaryEnergyCons!$C$4:$C$10000)*1,[1]OUT_PrimaryEnergyCons!H$4:H$10000)} -> 0.0011719605 | K25: {=SUMPRODUCT(("HFO"=[1]OUT_PrimaryEnergyCons!$C$4:$C$10000)*1,[1]OUT_PrimaryEnergyCons!I$4:I$10000)} -> 0.0010442686 | L25: {=SUMPRODUCT(("HFO"=[1]OUT_PrimaryEnergyCons!$C$4:$C$10000)*1,[1]OUT_PrimaryEnergyCons!J$4:J$10000)} -> 0.0011656933 | M25: {=SUMPRODUCT(("HFO"=[1]OUT_PrimaryEnergyCons!$C$4:$C$10000)*1,[1]OUT_PrimaryEnergyCons!K$4:K$10000)} -> 0 | ... Q25: {=SUMPRODUCT(("HFO"=[1]OUT_PrimaryEnergyCons!$C$4:$C$10000)*1,[1]OUT_PrimaryEnergyCons!O$4:O$10000)} -> 0
A26: =A25 -> STEM | B26: =B25 -> SPS1 | C26: =C25 -> CH | D26: Imports|Oil|Fossil liquids|Motor Diesel | E26: PJ/yr. | F26: {=SUMPRODUCT(("DSL"=[1]OUT_PrimaryEnergyCons!$C$4:$C$10000)*1,[1]OUT_PrimaryEnergyCons!D$4:D$10000)} -> 118.54821 | G26: {=SUMPRODUCT(("DSL"=[1]OUT_PrimaryEnergyCons!$C$4:$C$10000)*1,[1]OUT_PrimaryEnergyCons!E$4:E$10000)} -> 112.04192 | H26: {=SUMPRODUCT(("DSL"=[1]OUT_PrimaryEnergyCons!$C$4:$C$10000)*1,[1]OUT_PrimaryEnergyCons!F$4:F$10000)} -> 96.884526 | I26: {=SUMPRODUCT(("DSL"=[1]OUT_PrimaryEnergyCons!$C$4:$C$10000)*1,[1]OUT_PrimaryEnergyCons!G$4:G$10000)} -> 71.412412 | J26: {=SUMPRODUCT(("DSL"=[1]OUT_PrimaryEnergyCons!$C$4:$C$10000)*1,[1]OUT_PrimaryEnergyCons!H$4:H$10000)} -> 49.514288 | K26: {=SUMPRODUCT(("DSL"=[1]OUT_PrimaryEnergyCons!$C$4:$C$10000)*1,[1]OUT_PrimaryEnergyCons!I$4:I$10000)} -> 45.4305 | L26: {=SUMPRODUCT(("DSL"=[1]OUT_PrimaryEnergyCons!$C$4:$C$10000)*1,[1]OUT_PrimaryEnergyCons!J$4:J$10000)} -> 42.313798 | M26: {=SUMPRODUCT(("DSL"=[1]OUT_PrimaryEnergyCons!$C$4:$C$10000)*1,[1]OUT_PrimaryEnergyCons!K$4:K$10000)} -> 40.427301 | ... Q26: {=SUMPRODUCT(("DSL"=[1]OUT_PrimaryEnergyCons!$C$4:$C$10000)*1,[1]OUT_PrimaryEnergyCons!O$4:O$10000)} -> 29.599771
A27: =A26 -> STEM | B27: =B26 -> SPS1 | C27: =C26 -> CH | D27: Imports|Oil|Fossil liquids|Motor Gasoline | E27: PJ/yr. | F27: {=SUMPRODUCT(("GSL"=[1]OUT_PrimaryEnergyCons!$C$4:$C$10000)*1,[1]OUT_PrimaryEnergyCons!D$4:D$10000)} -> 79.788391 | G27: {=SUMPRODUCT(("GSL"=[1]OUT_PrimaryEnergyCons!$C$4:$C$10000)*1,[1]OUT_PrimaryEnergyCons!E$4:E$10000)} -> 75.956113 | H27: {=SUMPRODUCT(("GSL"=[1]OUT_PrimaryEnergyCons!$C$4:$C$10000)*1,[1]OUT_PrimaryEnergyCons!F$4:F$10000)} -> 79.808008 | I27: {=SUMPRODUCT(("GSL"=[1]OUT_PrimaryEnergyCons!$C$4:$C$10000)*1,[1]OUT_PrimaryEnergyCons!G$4:G$10000)} -> 58.363036 | J27: {=SUMPRODUCT(("GSL"=[1]OUT_PrimaryEnergyCons!$C$4:$C$10000)*1,[1]OUT_PrimaryEnergyCons!H$4:H$10000)} -> 44.723838 | K27: {=SUMPRODUCT(("GSL"=[1]OUT_PrimaryEnergyCons!$C$4:$C$10000)*1,[1]OUT_PrimaryEnergyCons!I$4:I$10000)} -> 38.520006 | L27: {=SUMPRODUCT(("GSL"=[1]OUT_PrimaryEnergyCons!$C$4:$C$10000)*1,[1]OUT_PrimaryEnergyCons!J$4:J$10000)} -> 33.156816 | M27: {=SUMPRODUCT(("GSL"=[1]OUT_PrimaryEnergyCons!$C$4:$C$10000)*1,[1]OUT_PrimaryEnergyCons!K$4:K$10000)} -> 28.671767 | ... Q27: {=SUMPRODUCT(("GSL"=[1]OUT_PrimaryEnergyCons!$C$4:$C$10000)*1,[1]OUT_PrimaryEnergyCons!O$4:O$10000)} -> 21.000276
A28: =A27 -> STEM | B28: =B27 -> SPS1 | C28: =C27 -> CH | D28: Imports|Oil|Fossil liquids|Kerosene (excl. international aviation) | E28: PJ/yr. | F28: {=SUMPRODUCT(("KER"=[1]OUT_PrimaryEnergyCons!$C$4:$C$10000)*1,[1]OUT_PrimaryEnergyCons!D$4:D$10000)} -> 1.1084624 | G28: {=SUMPRODUCT(("KER"=[1]OUT_PrimaryEnergyCons!$C$4:$C$10000)*1,[1]OUT_PrimaryEnergyCons!E$4:E$10000)} -> 1.4052016 | H28: {=SUMPRODUCT(("KER"=[1]OUT_PrimaryEnergyCons!$C$4:$C$10000)*1,[1]OUT_PrimaryEnergyCons!F$4:F$10000)} -> 1.8472809 | I28: {=SUMPRODUCT(("KER"=[1]OUT_PrimaryEnergyCons!$C$4:$C$10000)*1,[1]OUT_PrimaryEnergyCons!G$4:G$10000)} -> 1.6094252 | J28: {=SUMPRODUCT(("KER"=[1]OUT_PrimaryEnergyCons!$C$4:$C$10000)*1,[1]OUT_PrimaryEnergyCons!H$4:H$10000)} -> 1.1631901 | K28: {=SUMPRODUCT(("KER"=[1]OUT_PrimaryEnergyCons!$C$4:$C$10000)*1,[1]OUT_PrimaryEnergyCons!I$4:I$10000)} -> 0.9825278 | L28: {=SUMPRODUCT(("KER"=[1]OUT_PrimaryEnergyCons!$C$4:$C$10000)*1,[1]OUT_PrimaryEnergyCons!J$4:J$10000)} -> 0.66038873 | M28: {=SUMPRODUCT(("KER"=[1]OUT_PrimaryEnergyCons!$C$4:$C$10000)*1,[1]OUT_PrimaryEnergyCons!K$4:K$10000)} -> 0.38888635 | ... Q28: {=SUMPRODUCT(("KER"=[1]OUT_PrimaryEnergyCons!$C$4:$C$10000)*1,[1]OUT_PrimaryEnergyCons!O$4:O$10000)} -> 9.8002702e-05
A29: =A50 -> STEM | B29: =B50 -> SPS1 | C29: =C50 -> CH | D29: Imports|Oil|Synthetic liquids | E29: PJ/yr. | F29: =SUM(F30:F32) -> 6.835048 | G29: =SUM(G30:G32) -> 6.7766295 | H29: =SUM(H30:H32) -> 8.5432919 | I29: =SUM(I30:I32) -> 12.923703 | J29: =SUM(J30:J32) -> 11.657516 | K29: =SUM(K30:K32) -> 11.188824 | L29: =SUM(L30:L32) -> 11.019518 | M29: =SUM(M30:M32) -> 10.878241 | ... Q29: =SUM(Q30:Q32) -> 7.9908494
A30: =A37 -> STEM | B30: =B37 -> SPS1 | C30: =C37 -> CH | D30: Imports|Oil|Synthetic liquids|Total|Motor diesel | E30: PJ/yr. | F30: {=SUMPRODUCT(ISNUMBER(SEARCH("IMPBDS",[1]OUT_SyntheticFuels!$C$4:$C$1000))*1,("Var_Fout"=[1]OUT_SyntheticFuels!$B$4:$B$1000)*1,[1]OUT_SyntheticFuels!E$4:E$1000)-F32} -> 2.399987 | G30: {=SUMPRODUCT(ISNUMBER(SEARCH("IMPBDS",[1]OUT_SyntheticFuels!$C$4:$C$1000))*1,("Var_Fout"=[1]OUT_SyntheticFuels!$B$4:$B$1000)*1,[1]OUT_SyntheticFuels!F$4:F$1000)-G32} -> 2.3779994 | H30: {=SUMPRODUCT(ISNUMBER(SEARCH("IMPBDS",[1]OUT_SyntheticFuels!$C$4:$C$1000))*1,("Var_Fout"=[1]OUT_SyntheticFuels!$B$4:$B$1000)*1,[1]OUT_SyntheticFuels!G$4:G$1000)-H32} -> 3.9203692 | I30: {=SUMPRODUCT(ISNUMBER(SEARCH("IMPBDS",[1]OUT_SyntheticFuels!$C$4:$C$1000))*1,("Var_Fout"=[1]OUT_SyntheticFuels!$B$4:$B$1000)*1,[1]OUT_SyntheticFuels!H$4:H$1000)-I32} -> 2.3915775 | J30: {=SUMPRODUCT(ISNUMBER(SEARCH("IMPBDS",[1]OUT_SyntheticFuels!$C$4:$C$1000))*1,("Var_Fout"=[1]OUT_SyntheticFuels!$B$4:$B$1000)*1,[1]OUT_SyntheticFuels!I$4:I$1000)-J32} -> 1.8280361 | K30: {=SUMPRODUCT(ISNUMBER(SEARCH("IMPBDS",[1]OUT_SyntheticFuels!$C$4:$C$1000))*1,("Var_Fout"=[1]OUT_SyntheticFuels!$B$4:$B$1000)*1,[1]OUT_SyntheticFuels!J$4:J$1000)-K32} -> 1.863639 | L30: {=SUMPRODUCT(ISNUMBER(SEARCH("IMPBDS",[1]OUT_SyntheticFuels!$C$4:$C$1000))*1,("Var_Fout"=[1]OUT_SyntheticFuels!$B$4:$B$1000)*1,[1]OUT_SyntheticFuels!K$4:K$1000)-L32} -> 1.7608845 | M30: {=SUMPRODUCT(ISNUMBER(SEARCH("IMPBDS",[1]OUT_SyntheticFuels!$C$4:$C$1000))*1,("Var_Fout"=[1]OUT_SyntheticFuels!$B$4:$B$1000)*1,[1]OUT_SyntheticFuels!L$4:L$1000)-M32} -> 1.7059792 | ... Q30: {=SUMPRODUCT(ISNUMBER(SEARCH("IMPBDS",[1]OUT_SyntheticFuels!$C$4:$C$1000))*1,("Var_Fout"=[1]OUT_SyntheticFuels!$B$4:$B$1000)*1,[1]OUT_SyntheticFuels!P$4:P$1000)-Q32} -> -0.61141063
A31: =A30 -> STEM | B31: =B30 -> SPS1 | C31: =C30 -> CH | D31: Imports|Oil|Synthetic liquids|Total|Motor Gasoline | E31: PJ/yr. | F31: {=SUMPRODUCT(ISNUMBER(SEARCH("IMPeth",[1]OUT_SyntheticFuels!$C$4:$C$1000))*1,("Var_Fout"=[1]OUT_SyntheticFuels!$B$4:$B$1000)*1,[1]OUT_SyntheticFuels!E$4:E$1000)} -> 4.4341508 | G31: {=SUMPRODUCT(ISNUMBER(SEARCH("IMPeth",[1]OUT_SyntheticFuels!$C$4:$C$1000))*1,("Var_Fout"=[1]OUT_SyntheticFuels!$B$4:$B$1000)*1,[1]OUT_SyntheticFuels!F$4:F$1000)} -> 4.398616 | H31: {=SUMPRODUCT(ISNUMBER(SEARCH("IMPeth",[1]OUT_SyntheticFuels!$C$4:$C$1000))*1,("Var_Fout"=[1]OUT_SyntheticFuels!$B$4:$B$1000)*1,[1]OUT_SyntheticFuels!G$4:G$1000)} -> 4.6212683 | I31: {=SUMPRODUCT(ISNUMBER(SEARCH("IMPeth",[1]OUT_SyntheticFuels!$C$4:$C$1000))*1,("Var_Fout"=[1]OUT_SyntheticFuels!$B$4:$B$1000)*1,[1]OUT_SyntheticFuels!H$4:H$1000)} -> 4.122716 | J31: {=SUMPRODUCT(ISNUMBER(SEARCH("IMPeth",[1]OUT_SyntheticFuels!$C$4:$C$1000))*1,("Var_Fout"=[1]OUT_SyntheticFuels!$B$4:$B$1000)*1,[1]OUT_SyntheticFuels!I$4:I$1000)} -> 2.8977398 | K31: {=SUMPRODUCT(ISNUMBER(SEARCH("IMPeth",[1]OUT_SyntheticFuels!$C$4:$C$1000))*1,("Var_Fout"=[1]OUT_SyntheticFuels!$B$4:$B$1000)*1,[1]OUT_SyntheticFuels!J$4:J$1000)} -> 2.2310078 | L31: {=SUMPRODUCT(ISNUMBER(SEARCH("IMPeth",[1]OUT_SyntheticFuels!$C$4:$C$1000))*1,("Var_Fout"=[1]OUT_SyntheticFuels!$B$4:$B$1000)*1,[1]OUT_SyntheticFuels!K$4:K$1000)} -> 1.9204176 | M31: {=SUMPRODUCT(ISNUMBER(SEARCH("IMPeth",[1]OUT_SyntheticFuels!$C$4:$C$1000))*1,("Var_Fout"=[1]OUT_SyntheticFuels!$B$4:$B$1000)*1,[1]OUT_SyntheticFuels!L$4:L$1000)} -> 1.6609129 | ... Q31: {=SUMPRODUCT(ISNUMBER(SEARCH("IMPeth",[1]OUT_SyntheticFuels!$C$4:$C$1000))*1,("Var_Fout"=[1]OUT_SyntheticFuels!$B$4:$B$1000)*1,[1]OUT_SyntheticFuels!P$4:P$1000)} -> 1.216944
B32: =B31 -> SPS1 | C32: =C31 -> CH | D32: Imports|Oil|Synthetic liquids|Total|Kerosene | E32: PJ/yr. | F32: =SUM([1]Transport_Aviation_Intl!B$12,[1]Transport!B$28) -> 0.00091022248 | G32: =SUM([1]Transport_Aviation_Intl!C$12,[1]Transport!C$28) -> 1.4106315e-05 | H32: =SUM([1]Transport_Aviation_Intl!D$12,[1]Transport!D$28) -> 0.0016544428 | I32: =SUM([1]Transport_Aviation_Intl!E$12,[1]Transport!E$28) -> 6.4094097 | J32: =SUM([1]Transport_Aviation_Intl!F$12,[1]Transport!F$28) -> 6.9317401 | K32: =SUM([1]Transport_Aviation_Intl!G$12,[1]Transport!G$28) -> 7.0941776 | L32: =SUM([1]Transport_Aviation_Intl!H$12,[1]Transport!H$28) -> 7.3382163 | M32: =SUM([1]Transport_Aviation_Intl!I$12,[1]Transport!I$28) -> 7.5113488 | ... Q32: =SUM([1]Transport_Aviation_Intl!M$12,[1]Transport!M$28) -> 7.385316
A33: =A29 -> STEM | B33: =B29 -> SPS1 | C33: =C29 -> CH | D33: Imports|Oil|Synthetic liquids|Bioliquids|Total | E33: PJ/yr. | F33: =SUM(F34:F36) -> 6.835048 | G33: =SUM(G34:G36) -> 6.7766295 | H33: =SUM(H34:H36) -> 8.5432919 | I33: =SUM(I34:I36) -> 12.923703 | J33: =SUM(J34:J36) -> 11.135186 | K33: =SUM(K34:K36) -> 11.026387 | L33: =SUM(L34:L36) -> 10.77548 | M33: =SUM(M34:M36) -> 10.705108 | ... Q33: =SUM(Q34:Q36) -> 7.9908494
A34: =A31 -> STEM | B34: =B31 -> SPS1 | C34: =C31 -> CH | D34: Imports|Oil|Synthetic liquids|Bioliquids|Biodiesel | E34: PJ/yr. | F34: =F30 -> 2.399987 | G34: =G30 -> 2.3779994 | H34: =H30 -> 3.9203692 | I34: =I30 -> 2.3915775 | J34: =IF(J30-MAX(F30:I30)<0,J30,MAX(F30:I30)) -> 1.8280361 | K34: =IF(K30-MAX(F30:J30)<0,K30,MAX(F30:J30)) -> 1.863639 | L34: =IF(L30-MAX(G30:K30)<0,L30,MAX(G30:K30)) -> 1.7608845 | M34: =IF(M30-MAX(H30:L30)<0,M30,MAX(H30:L30)) -> 1.7059792 | N34: =IF(N30-MAX(I30:M30)<0,N30,MAX(I30:M30)) -> 1.6907608 | O34: =IF(O30-MAX(J30:N30)<0,O30,MAX(J30:N30)) -> 1.5027284 | P34: =IF(P30-MAX(K30:O30)<0,P30,MAX(K30:O30)) -> 0.025355221 | Q34: =IF(Q30-MAX(L30:P30)<0,Q30,MAX(L30:P30)) -> -0.61141063
A35: =A34 -> STEM | B35: =B34 -> SPS1 | C35: =C34 -> CH | D35: Imports|Oil|Synthetic liquids|Bioliquids|Ethanol | E35: PJ/yr. | F35: =F31 -> 4.4341508 | G35: =G31 -> 4.398616 | H35: =H31 -> 4.6212683 | I35: =I31 -> 4.122716 | J35: =IF(J31-MAX(F31:I31)<0,J31,MAX(F31:I31)) -> 2.8977398 | K35: =IF(K31-MAX(F31:J31)<0,K31,MAX(F31:J31)) -> 2.2310078 | L35: =IF(L31-MAX(G31:K31)<0,L31,MAX(G31:K31)) -> 1.9204176 | M35: =IF(M31-MAX(H31:L31)<0,M31,MAX(H31:L31)) -> 1.6609129 | N35: =IF(N31-MAX(I31:M31)<0,N31,MAX(I31:M31)) -> 1.5118459 | O35: =IF(O31-MAX(J31:N31)<0,O31,MAX(J31:N31)) -> 1.3751733 | P35: =IF(P31-MAX(K31:O31)<0,P31,MAX(K31:O31)) -> 1.2711444 | Q35: =IF(Q31-MAX(L31:P31)<0,Q31,MAX(L31:P31)) -> 1.216944
B36: =B35 -> SPS1 | C36: =C35 -> CH | D36: Imports|Oil|Synthetic liquids|Bioliquids|Biokerosene | E36: PJ/yr. | F36: =SUM([1]Transport!B$28,[1]Transport_Aviation_Intl!B$12) -> 0.00091022248 | G36: =SUM([1]Transport!C$28,[1]Transport_Aviation_Intl!C$12) -> 1.4106315e-05 | H36: =SUM([1]Transport!D$28,[1]Transport_Aviation_Intl!D$12) -> 0.0016544428 | I36: =SUM([1]Transport!E$28,[1]Transport_Aviation_Intl!E$12) -> 6.4094097 | J36: =IF(J32-MAX(F32:I32)<0,J32,MAX(F32:I32)) -> 6.4094097 | K36: =IF(K32-MAX(G32:J32)<0,K32,MAX(G32:J32)) -> 6.9317401 | L36: =IF(L32-MAX(H32:K32)<0,L32,MAX(H32:K32)) -> 7.0941776 | M36: =IF(M32-MAX(I32:L32)<0,M32,MAX(I32:L32)) -> 7.3382163 | N36: =IF(N32-MAX(J32:M32)<0,N32,MAX(J32:M32)) -> 7.5113488 | O36: =IF(O32-MAX(K32:N32)<0,O32,MAX(K32:N32)) -> 7.519747 | P36: =IF(P32-MAX(L32:O32)<0,P32,MAX(L32:O32)) -> 7.4073901 | Q36: =IF(Q32-MAX(M32:P32)<0,Q32,MAX(M32:P32)) -> 7.385316
A37: =A33 -> STEM | B37: =B33 -> SPS1 | C37: =C33 -> CH | D37: Imports|Oil|Synthetic liquids|PtL|Total | E37: PJ/yr. | F37: =SUM(F38:F40) -> 0 | G37: =SUM(G38:G40) -> 0 | H37: =SUM(H38:H40) -> 0 | I37: =SUM(I38:I40) -> 0 | J37: =SUM(J38:J40) -> 0.52233044 | K37: =SUM(K38:K40) -> 0.16243754 | L37: =SUM(L38:L40) -> 0.24403865 | M37: =SUM(M38:M40) -> 0.17313251 | ... Q37: =SUM(Q38:Q40) -> 0
A38: =A35 -> STEM | B38: =B35 -> SPS1 | C38: =C35 -> CH | D38: Imports|Oil|Synthetic liquids|PtL|PtL Diesel | E38: PJ/yr. | F38: 0 | G38: 0 | H38: 0 | I38: 0 | J38: =J30-J34 -> 0 | K38: =K30-K34 -> 0 | L38: =L30-L34 -> 0 | M38: =M30-M34 -> 0 | N38: =N30-N34 -> 0 | O38: =O30-O34 -> 0 | P38: =P30-P34 -> 0 | Q38: =Q30-Q34 -> 0
A39: =A38 -> STEM | B39: =B38 -> SPS1 | C39: =C38 -> CH | D39: Imports|Oil|Synthetic liquids|PtL|PtL Gasoline | E39: PJ/yr. | F39: 0 | G39: 0 | H39: 0 | I39: 0 | J39: =J31-J35 -> 0 | K39: =K31-K35 -> 0 | L39: =L31-L35 -> 0 | M39: =M31-M35 -> 0 | N39: =N31-N35 -> 0 | O39: =O31-O35 -> 0 | P39: =P31-P35 -> 0 | Q39: =Q31-Q35 -> 0
B40: =B39 -> SPS1 | C40: =C39 -> CH | D40: Imports|Oil|Synthetic liquids|PtL|PtL Kerosene | E40: PJ/yr. | F40: 0 | G40: 0 | H40: 0 | I40: 0 | J40: =J32-J36 -> 0.52233044 | K40: =K32-K36 -> 0.16243754 | L40: =L32-L36 -> 0.24403865 | M40: =M32-M36 -> 0.17313251 | N40: =N32-N36 -> 0.0083981758 | O40: =O32-O36 -> 0.031962696 | P40: =P32-P36 -> 0 | Q40: =Q32-Q36 -> 0
...

Sheet check
C2: 2020 | D2: 2022 | E2: 2025 | F2: 2030 | G2: 2040 | H2: 2050
B3: Final energy consumption | C3: =SUM(C4:C7) -> 695.76536 | D3: =SUM(D4:D7) -> 686.39324 | E3: =SUM(E4:E7) -> 683.5804 | F3: =SUM(F4:F7) -> 647.53002 | G3: =SUM(G4:G7) -> 618.76501 | H3: =SUM(H4:H7) -> 607.72862
B4: Industry | C4: ='SPS1'!F763 -> 142.21735 | D4: ='SPS1'!G763 -> 141.10818 | E4: ='SPS1'!H763 -> 142.87343 | F4: ='SPS1'!I763 -> 144.14519 | G4: ='SPS1'!J763 -> 145.42241 | H4: ='SPS1'!K763 -> 146.31463
B5: Services | C5: ='SPS1'!F882 -> 140.10106 | D5: ='SPS1'!G882 -> 139.65428 | E5: ='SPS1'!H882 -> 141.57543 | F5: ='SPS1'!I882 -> 139.75812 | G5: ='SPS1'!J882 -> 135.81273 | H5: ='SPS1'!K882 -> 132.4696
B6: Residential | C6: ='SPS1'!F972 -> 217.24196 | D6: ='SPS1'!G972 -> 218.17129 | E6: ='SPS1'!H972 -> 216.09504 | F6: ='SPS1'!I972 -> 215.31315 | G6: ='SPS1'!J972 -> 213.96437 | H6: ='SPS1'!K972 -> 210.85662
B7: Transport | C7: ='SPS1'!F1136+'SPS1'!F1315+'SPS1'!F1399+'SPS1'!F1483+'SPS1'!F1490+'SPS1'!F1497+'SPS1'!F1546+'SPS1'!F1593+'SPS1'!F1640 -> 196.20499 | D7: ='SPS1'!G1136+'SPS1'!G1315+'SPS1'!G1399+'SPS1'!G1483+'SPS1'!G1490+'SPS1'!G1497+'SPS1'!G1546+'SPS1'!G1593+'SPS1'!G1640 -> 187.45949 | E7: ='SPS1'!H1136+'SPS1'!H1315+'SPS1'!H1399+'SPS1'!H1483+'SPS1'!H1490+'SPS1'!H1497+'SPS1'!H1546+'SPS1'!H1593+'SPS1'!H1640 -> 183.0365 | F7: ='SPS1'!I1136+'SPS1'!I1315+'SPS1'!I1399+'SPS1'!I1483+'SPS1'!I1490+'SPS1'!I1497+'SPS1'!I1546+'SPS1'!I1593+'SPS1'!I1640 -> 148.31357 | G7: ='SPS1'!J1136+'SPS1'!J1315+'SPS1'!J1399+'SPS1'!J1483+'SPS1'!J1490+'SPS1'!J1497+'SPS1'!J1546+'SPS1'!J1593+'SPS1'!J1640 -> 123.56551 | H7: ='SPS1'!K1136+'SPS1'!K1315+'SPS1'!K1399+'SPS1'!K1483+'SPS1'!K1490+'SPS1'!K1497+'SPS1'!K1546+'SPS1'!K1593+'SPS1'!K1640 -> 118.08777
B8: Fuel input to energy conversion and DAC | C8: =SUM(C9:C12) -> 509.38509 | D8: =SUM(D9:D12) -> 501.00729 | E8: =SUM(E9:E12) -> 507.89382 | F8: =SUM(F9:F12) -> 544.00849 | G8: =SUM(G9:G12) -> 504.9434 | H8: =SUM(H9:H12) -> 436.7548
B9: Electricity and heat | C9: ='SPS1'!F291+'SPS1'!F409 -> 493.40859 | D9: ='SPS1'!G291+'SPS1'!G409 -> 476.69799 | E9: ='SPS1'!H291+'SPS1'!H409 -> 483.9518 | F9: ='SPS1'!I291+'SPS1'!I409 -> 521.58141 | G9: ='SPS1'!J291+'SPS1'!J409 -> 482.52178 | H9: ='SPS1'!K291+'SPS1'!K409 -> 414.59929
B10: Biofuel production | C10: ='SPS1'!F590+'SPS1'!F604+'SPS1'!F644 -> 15.971634 | D10: ='SPS1'!G590+'SPS1'!G604+'SPS1'!G644 -> 24.30298 | E10: ='SPS1'!H590+'SPS1'!H604+'SPS1'!H644 -> 23.935789 | F10: ='SPS1'!I590+'SPS1'!I604+'SPS1'!I644 -> 22.419403 | G10: ='SPS1'!J590+'SPS1'!J604+'SPS1'!J644 -> 22.398518 | H10: ='SPS1'!K590+'SPS1'!K604+'SPS1'!K644 -> 22.123444
B11: Hydrogen production | C11: ='SPS1'!F679 -> 0.0048643861 | D11: ='SPS1'!G679 -> 0.0063181158 | E11: ='SPS1'!H679 -> 0.0062251234 | F11: ='SPS1'!I679 -> 0.0076816396 | G11: ='SPS1'!J679 -> 0.02309369 | H11: ='SPS1'!K679 -> 0.032059063
B12: DAC | C12: ='SPS1'!F1707 -> 0 | D12: ='SPS1'!G1707 -> 0 | E12: ='SPS1'!H1707 -> 0 | F12: ='SPS1'!I1707 -> 0 | G12: ='SPS1'!J1707 -> 0 | H12: ='SPS1'!K1707 -> 0
B13: Total Primary energy consumption | C13: ='SPS1'!F2+'SPS1'!F20-'SPS1'!F57 -> 962.36773 | D13: ='SPS1'!G2+'SPS1'!G20-'SPS1'!G57 -> 962.32714 | E13: ='SPS1'!H2+'SPS1'!H20-'SPS1'!H57 -> 924.48863 | F13: ='SPS1'!I2+'SPS1'!I20-'SPS1'!I57 -> 897.69606 | G13: ='SPS1'!J2+'SPS1'!J20-'SPS1'!J57 -> 835.10741 | H13: ='SPS1'!K2+'SPS1'!K20-'SPS1'!K57 -> 775.47743
B14: Domestic production | C14: ='SPS1'!F2 -> 299.98379 | D14: ='SPS1'!G2 -> 295.49195 | E14: ='SPS1'!H2 -> 331.44694 | F14: ='SPS1'!I2 -> 365.47345 | G14: ='SPS1'!J2 -> 376.67392 | H14: ='SPS1'!K2 -> 382.65095
B15: Imports | C15: ='SPS1'!F20 -> 779.55394 | D15: ='SPS1'!G20 -> 702.62669 | E15: ='SPS1'!H20 -> 657.4738 | F15: ='SPS1'!I20 -> 613.5139 | G15: ='SPS1'!J20 -> 523.94075 | H15: ='SPS1'!K20 -> 436.22267
B16: Exports | C16: ='SPS1'!F57 -> 117.17 | D16: ='SPS1'!G57 -> 35.79151 | E16: ='SPS1'!H57 -> 64.432103 | F16: ='SPS1'!I57 -> 81.291294 | G16: ='SPS1'!J57 -> 65.507257 | H16: ='SPS1'!K57 -> 43.396189
